Workbook

Sheet INCOME STATEMENT
A1: CONSOLIDATED STATEMENTS OF OPERATIONS - USD ($) | B1: 12 Months Ended
A2: shares in Thousands, $ in Millions | B2: Sep. 30, 2023 | C2: Sep. 28, 2024 | D2: Sep. 27, 2025
A3: Net sales | B3: 383285 | C3: 391035 | D3: 416161
A4: Cost of sales | B4: 214137 | C4: 210352 | D4: 220960
A5: Gross margin | B5: 169148 | C5: 180683 | D5: 195201
A6: Operating expenses:
A7: Research and development | B7: 29915 | C7: 31370 | D7: 34550
A8: Selling, general and administrative | B8: 24932 | C8: 26097 | D8: 27601
A9: Total operating expenses | B9: 54847 | C9: 57467 | D9: 62151
A10: Operating income | B10: 114301 | C10: 123216 | D10: 133050
A11: Other income/(expense), net | B11: -565 | C11: 269 | D11: -321
A12: Income before provision for income taxes | B12: 113736 | C12: 123485 | D12: 132729
A13: Provision for income taxes | B13: 16741 | C13: 29749 | D13: 20719
A14: Net income | B14: 96995 | C14: 93736 | D14: 112010
A15: Earnings per share:
A16: Basic (in dollars per share) | B16: 6.16 | C16: 6.11 | D16: 7.49
A17: Diluted (in dollars per share) | B17: 6.13 | C17: 6.08 | D17: 7.46
A18: Shares used in computing earnings per share:
A19: Basic (in shares) | B19: 15744231 | C19: 15343783 | D19: 14948500
A20: Diluted (in shares) | B20: 15812547 | C20: 15408095 | D20: 15004697
A21: Products
A22: Net sales | B22: 298085 | C22: 294866 | D22: 307003
A23: Cost of sales | B23: 189282 | C23: 185233 | D23: 194116
A24: Services
A25: Net sales | B25: 85200 | C25: 96169 | D25: 109158
A26: Cost of sales | B26: 24855 | C26: 25119 | D26: 26844

Sheet Balance Sheet
A1: CONSOLIDATED BALANCE SHEETS - USD ($) | B1: Sep. 30, 2023 | C1: Sep. 28, 2024 | D1: Sep. 27, 2025
A2: Current assets:
A3: Cash and cash equivalents | B3: 29965 | C3: 29943 | D3: 35934
A4: Marketable securities | B4: 31590 | C4: 35228 | D4: 18763
A5: Accounts receivable, net | B5: 29508 | C5: 33410 | D5: 39777
A6: Vendor non-trade receivables | B6: 31477 | C6: 32833 | D6: 33180
A7: Inventories | B7: 6331 | C7: 7286 | D7: 5718
A8: Other current assets | B8: 14695 | C8: 14287 | D8: 14585
A9: Total current assets | B9: 143566 | C9: 152987 | D9: 147957
A10: Non-current assets:
A11: Marketable securities | B11: 100544 | C11: 91479 | D11: 77723
A12: Property, plant and equipment, net | B12: 43715 | C12: 45680 | D12: 49834
A13: Other non-current assets | B13: 64758 | C13: 74834 | D13: 83727
A14: Total non-current assets | B14: 209017 | C14: 211993 | D14: 211284
A15: Total assets | B15: 352583 | C15: 364980 | D15: 359241
A16: Current liabilities:
A17: Accounts payable | B17: 62611 | C17: 68960 | D17: 69860
A18: Other current liabilities | B18: 58829 | C18: 78304 | D18: 66387
A19: Deferred revenue | B19: 8061 | C19: 8249 | D19: 9055
A20: Commercial paper | B20: 5985 | C20: 9967 | D20: 7979
A21: Term debt | B21: 9822 | C21: 10912 | D21: 12350
A22: Total current liabilities | B22: 145308 | C22: 176392 | D22: 165631
A23: Non-current liabilities:
A24: Term debt | B24: 95281 | C24: 85750 | D24: 78328
A25: Other non-current liabilities | B25: 49848 | C25: 45888 | D25: 41549
A26: Total non-current liabilities | B26: 145129 | C26: 131638 | D26: 119877
A27: Total liabilities | B27: 290437 | C27: 308030 | D27: 285508
A28: Commitments and contingencies
A29: Common stock, shares outstanding (in shares) | B29: 15550061 | C29: 15116786 | D29: 14773260
A30: Common stock, shares issued (in shares) | B30: 15550061 | C30: 15116786 | D30: 14773260
A31: Shareholders’ equity:
A32: Common stock and additional paid-in capital, $0.00001 par value: 50,400,000 shares authorized; 14,773,260 and 15,116,786 shares issued and outstanding, respectively | B32: 73812 | C32: 83276 | D32: 93568
A33: Accumulated deficit | B33: -214 | C33: -19154 | D33: -14264
A34: Accumulated other comprehensive loss | B34: -11452 | C34: -7172 | D34: -5571
A35: Total shareholders’ equity | B35: 62146 | C35: 56950 | D35: 73733
A36: Total liabilities and shareholders’ equity | B36: 352583 | C36: 364980 | D36: 359241

Sheet CASH FLOW
A1: CONSOLIDATED STATEMENTS OF CASH FLOWS - USD ($) | B1: 12 Months Ended
A2: $ in Millions | B2: Sep. 30, 2023 | C2: Sep. 28, 2024 | D2: Sep. 27, 2025
A3: Statement of Cash Flows [Abstract]
A4: Cash, cash equivalents, and restricted cash and cash equivalents, beginning balances | B4: 24977 | C4: 30737 | D4: 29943
A5: Operating activities:
A6: Net income | B6: 96995 | C6: 93736 | D6: 112010
A7: Adjustments to reconcile net income to cash generated by operating activities:
A8: Depreciation and amortization | B8: 11519 | C8: 11445 | D8: 11698
A9: Share-based compensation expense | B9: 10833 | C9: 11688 | D9: 12863
A10: Other | B10: -2227 | C10: -2266 | D10: -89
A11: Changes in operating assets and liabilities:
A12: Accounts receivable, net | B12: -1688 | C12: -3788 | D12: -6682
A13: Vendor non-trade receivables | B13: 1271 | C13: -1356 | D13: -347
A14: Inventories | B14: -1618 | C14: -1046 | D14: 1400
A15: Other current and non-current assets | B15: -5684 | C15: -11731 | D15: -9197
A16: Accounts payable | B16: -1889 | C16: 6020 | D16: 902
A17: Other current and non-current liabilities | B17: 3031 | C17: 15552 | D17: -11076
A18: Cash generated by operating activities | B18: 110543 | C18: 118254 | D18: 111482
A19: Investing activities:
A20: Purchases of marketable securities | B20: -29513 | C20: -48656 | D20: -24407
A21: Proceeds from maturities of marketable securities | B21: 39686 | C21: 51211 | D21: 40907
A22: Proceeds from sales of marketable securities | B22: 5828 | C22: 11135 | D22: 12890
A23: Payments for acquisition of property, plant and equipment | B23: -10959 | C23: -9447 | D23: -12715
A24: Other | B24: -1337 | C24: -1308 | D24: -1480
A25: Cash generated by investing activities | B25: 3705 | C25: 2935 | D25: 15195
A26: Financing activities:
A27: Payments for taxes related to net share settlement of equity awards | B27: -5431 | C27: -5441 | D27: -5960
A28: Payments for dividends and dividend equivalents | B28: -15025 | C28: -15234 | D28: -15421
A29: Repurchases of common stock | B29: -77550 | C29: -94949 | D29: -90711
A30: Proceeds from issuance of term debt, net | B30: 5228 | C30: 0 | D30: 4481
A31: Repayments of term debt | B31: -11151 | C31: -9958 | D31: -10932
A32: Proceeds from/(Repayments of) commercial paper, net | B32: -3978 | C32: 3960 | D32: -2032
A33: Other | B33: -581 | C33: -361 | D33: -111
A34: Cash used in financing activities | B34: -108488 | C34: -121983 | D34: -120686
A35: Increase/(Decrease) in cash, cash equivalents, and restricted cash and cash equivalents | B35: 5760 | C35: -794 | D35: 5991
A36: Cash, cash equivalents, and restricted cash and cash equivalents, ending balances | B36: 30737 | C36: 29943 | D36: 35934
A37: Supplemental cash flow disclosure:
A38: Cash paid for income taxes, net | B38: 18679 | C38: 26102 | D38: 43369

Sheet PROYECCIONES
A1: Unlevered Free Cash Flow (mm)
A2: Fiscal Year | B2: 45122 | C2: 45489 | D2: 45856 | E2: 46223 | F2: 46590 | G2: 46957 | H2: 47324 | I2: 47691
A3: Revenue | B3: ='INCOME STATEMENT'!B3 -> 383285 | C3: ='INCOME STATEMENT'!C3 -> 391035 | D3: ='INCOME STATEMENT'!D3 -> 416161 | E3: =D3*(1+E25) -> 434888.24 | F3: =E3*(1+F25) -> 454458.22 | G3: =F3*(1+G25) -> 474908.84 | H3: =G3*(1+H25) -> 496279.73 | I3: =H3*(1+I25) -> 518612.32
A4: COGS | B4: ='INCOME STATEMENT'!B4 -> 214137 | C4: ='INCOME STATEMENT'!C4 -> 210352 | D4: ='INCOME STATEMENT'!D4 -> 220960 | E4: =E27*E3 -> 235937.54 | F4: =F27*F3 -> 246554.73 | G4: =G27*G3 -> 257649.69 | H4: =H27*H3 -> 269243.92 | I4: =I27*I3 -> 281359.9
A5: Gross Profit | B5: =B3-B4 -> 169148 | C5: =C3-C4 -> 180683 | D5: =D3-D4 -> 195201 | E5: =E3-E4 -> 198950.71 | F5: =F3-F4 -> 207903.49 | G5: =G3-G4 -> 217259.15 | H5: =H3-H4 -> 227035.81 | I5: =I3-I4 -> 237252.42
A6: Operating Expenses
A7: Selling, General, Administrative | B7: ='INCOME STATEMENT'!B8 -> 24932 | C7: ='INCOME STATEMENT'!C8 -> 26097 | D7: ='INCOME STATEMENT'!D8 -> 27601 | E7: =E3*E28 -> 28718.478 | F7: =F3*F28 -> 30010.809 | G7: =G3*G28 -> 31361.296 | H7: =H3*H28 -> 32772.554 | I7: =I3*I28 -> 34247.319
A8: Research and development | B8: ='INCOME STATEMENT'!B7 -> 29915 | C8: ='INCOME STATEMENT'!C7 -> 31370 | D8: ='INCOME STATEMENT'!D7 -> 34550 | E8: =E3*E29 -> 34978.456 | F8: =F3*F29 -> 36552.487 | G8: =G3*G29 -> 38197.349 | H8: =H3*H29 -> 39916.229 | I8: =I3*I29 -> 41712.46
A9: Total Operating Expenses | B9: =SUM(B7:B8) -> 54847 | C9: =SUM(C7:C8) -> 57467 | D9: =SUM(D7:D8) -> 62151 | E9: =SUM(E7:E8) -> 63696.934 | F9: =SUM(F7:F8) -> 66563.296 | G9: =SUM(G7:G8) -> 69558.644 | H9: =SUM(H7:H8) -> 72688.783 | I9: =SUM(I7:I8) -> 75959.779
A10: EBITDA | B10: =B5-B9 -> 114301 | C10: =C5-C9 -> 123216 | D10: =D5-D9 -> 133050 | E10: =E5-E9 -> 135253.77 | F10: =F5-F9 -> 141340.19 | G10: =G5-G9 -> 147700.5 | H10: =H5-H9 -> 154347.03 | I10: =I5-I9 -> 161292.64
A11: Depreciation & Amortization | B11: 11519 | C11: 11445 | D11: 11698 | E11: =E36 -> 13146.131 | F11: =F36 -> 13907.857 | G11: =G36 -> 14713.721 | H11: =H36 -> 15566.279 | I11: =I36 -> 16468.236
A12: Operating Profit (EBIT) | B12: =B10-B11 -> 102782 | C12: =C10-C11 -> 111771 | D12: =D10-D11 -> 121352 | E12: =E10-E11 -> 122107.64 | F12: =F10-F11 -> 127432.34 | G12: =G10-G11 -> 132986.78 | H12: =H10-H11 -> 138780.75 | I12: =I10-I11 -> 144824.4
A13: Operating Taxes | B13: 16741 | C13: 29749 | D13: 20719 | E13: =E12*E30 -> 24412.318 | F13: =F12*F30 -> 25476.855 | G13: =G12*G30 -> 26587.325 | H13: =H12*H30 -> 27745.681 | I13: =I12*I30 -> 28953.957
A14: NOPAT (Net Operating Profit After Taxes) | B14: =B12-B13 -> 86041 | C14: =C12-C13 -> 82022 | D14: =D12-D13 -> 100633 | E14: =E12-E13 -> 97695.325 | F14: =F12-F13 -> 101955.48 | G14: =G12-G13 -> 106399.46 | H14: =H12-H13 -> 111035.07 | I14: =I12-I13 -> 115870.45
A15: (+) Depreciation & Amortization | B15: =B11 -> 11519 | C15: =C11 -> 11445 | D15: =D11 -> 11698 | E15: =E36 -> 13146.131 | F15: =F36 -> 13907.857 | G15: =G36 -> 14713.721 | H15: =H36 -> 15566.279 | I15: =I36 -> 16468.236
A16: (-) Capital Expenditures | B16: -10959 | C16: -9447 | D16: -12715 | E16: =-78%*E37 -> -12506.258 | F16: =-78%*F37 -> -13230.909 | G16: =-78%*G37 -> -13997.548 | H16: =-78%*H37 -> -14808.608 | I16: =-78%*I37 -> -15666.664
A17: (-) Change in NWC | B17: 16835 | C17: =C18-B18 -> -21563 | D17: =D18-C18 -> 15308 | E17: =E18-D18 -> -3513.3233 | F17: =F18-E18 -> -3993.0895 | G17: =G18-F18 -> -4172.7786 | H17: =H18-G18 -> -4360.5536 | I17: =I18-H18 -> -4556.7785
A18: NWC | B18: =B19-B20 -> -78967 | C18: =C19-C20 -> -100530 | D18: =D19-D20 -> -85222 | E18: =E19-E20 -> -88735.323 | F18: =F19-F20 -> -92728.413 | G18: =G19-G20 -> -96901.191 | H18: =H19-H20 -> -101261.75 | I18: =I19-I20 -> -105818.52
A19: Current Assets | B19: =C52 -> 50534 | C19: =D52 -> 54983 | D19: =E52 -> 60080 | E19: =F52 -> 60303.515 | F19: =G52 -> 63017.174 | G19: =H52 -> 65852.946 | H19: =I52 -> 68816.329 | I19: =J52 -> 71913.064
A20: Current Liabilitites | B20: =C57 -> 129501 | C20: =D57 -> 155513 | D20: =E57 -> 145302 | E20: =F57 -> 149038.84 | F20: =G57 -> 155745.59 | G20: =H57 -> 162754.14 | H20: =I57 -> 170078.07 | I20: =J57 -> 177731.59
A21: Unlevered Free Cash Flow | B21: =SUM(B14:B17) -> 103436 | C21: =SUM(C14:C17) -> 62457 | D21: =SUM(D14:D17) -> 114924 | E21: =SUM(E14:E17) -> 94821.874 | F21: =SUM(F14:F17) -> 98639.34 | G21: =SUM(G14:G17) -> 102942.85 | H21: =SUM(H14:H17) -> 107432.18 | I21: =SUM(I14:I17) -> 112115.24
A23: Assumptions | K23: JUSTIFICION
A24: Fiscal Year | B24: 43830 | C24: 44196 | D24: 44561 | E24: 44926 | F24: 45291 | G24: 45657 | H24: 46022 | I24: 46387 | K24: Dado que Apple Inc. es una compañía relativamente madura, con una base de ingresos diversificada y estable, se tomó como punto de partida el crecimiento histórico de los años anteriores para la proyección de ingresos. Este enfoque permite anclar las estimaciones en el desempeño observado y evitar supuestos excesivamente optimistas. No obstante, se considera un crecimiento moderadamente superior al histórico debido a factores estratégicos específicos de la compañía. En particular, Apple ha venido ejecutando una estrategia de relocalización y expansión de su capacidad productiva en India, así como un incremento progresivo de su participación en mercados asiáticos, lo que amplía su base de consumidores y reduce riesgos operativos. Adicionalmente, la fortaleza de su ecosistema, la elevada lealtad de sus clientes y el posicionamiento de marca ,especialmente en su línea iPhone, le otorgan un significativo poder de fijación de precios. A ello se suma la contribución creciente de segmentos de mayor margen, como servicios, lo que respalda la sostenibilidad de sus márgenes operativos. En conjunto, estos factores justifican la adopción de una tasa de crecimiento anual de ingresos del 4.5% para los próximos años, la cual se mantiene dentro de un rango razonable para una empresa madura y es consistente con su ventaja competitiva y su capacidad de generación de valor en el mediano plazo.
A25: Revenue Growth | B25: CAGR ( 5 años) | D25: =3.27%+1.23% -> 0.045 | E25: =$D$25 -> 0.045 | F25: =$D$25 -> 0.045 | G25: =$D$25 -> 0.045 | H25: =$D$25 -> 0.045 | I25: =$D$25 -> 0.045
A27: COGS % of Revenue | B27: =B4/B3 -> 0.5586887 | C27: =C4/C3 -> 0.5379365 | D27: =D4/D3 -> 0.53094836 | E27: =AVERAGE($B$27:$D$27) -> 0.54252452 | F27: =AVERAGE($B$27:$D$27) -> 0.54252452 | G27: =AVERAGE($B$27:$D$27) -> 0.54252452 | H27: =AVERAGE($B$27:$D$27) -> 0.54252452 | I27: =AVERAGE($B$27:$D$27) -> 0.54252452
A28: SG&A % of Revenue | B28: =B7/B3 -> 0.065048202 | C28: =C7/C3 -> 0.066738272 | D28: =D7/D3 -> 0.066322889 | E28: =AVERAGE($B$28:$D$28) -> 0.066036454 | F28: =AVERAGE($B$28:$D$28) -> 0.066036454 | G28: =AVERAGE($B$28:$D$28) -> 0.066036454 | H28: =AVERAGE($B$28:$D$28) -> 0.066036454 | I28: =AVERAGE($B$28:$D$28) -> 0.066036454
A29: Research and development | B29: =B8/B3 -> 0.078048971 | C29: =C8/C3 -> 0.080222998 | D29: =D8/D3 -> 0.083020754 | E29: =AVERAGE($B$29:$D$29) -> 0.080430908 | F29: =AVERAGE($B$29:$D$29) -> 0.080430908 | G29: =AVERAGE($B$29:$D$29) -> 0.080430908 | H29: =AVERAGE($B$29:$D$29) -> 0.080430908 | I29: =AVERAGE($B$29:$D$29) -> 0.080430908
A30: Tax % of EBIT | B30: =B13/B12 -> 0.16287871 | C30: =C13/C12 -> 0.26616027 | D30: =D13/D12 -> 0.17073472 | E30: =AVERAGE($B$30:$D$30) -> 0.19992457 | F30: =AVERAGE($B$30:$D$30) -> 0.19992457 | G30: =AVERAGE($B$30:$D$30) -> 0.19992457 | H30: =AVERAGE($B$30:$D$30) -> 0.19992457 | I30: =AVERAGE($B$30:$D$30) -> 0.19992457
A33: Fixed Assets Schedule
A34: Fiscal Year | B34: 45122 | C34: 45489 | D34: 45856 | E34: 46223 | F34: 46590 | G34: 46957 | H34: 47324 | I34: 47691
A35: Beginning PP&E | B35: 42117 | C35: 43715 | D35: 45680 | E35: =D38 -> 49834 | F35: =E38 -> 52721.533 | G35: =F38 -> 55776.379 | H35: =G38 -> 59008.232 | I35: =H38 -> 62427.349
A36: D&A | B36: 11519 | C36: 11445 | D36: 11698 | E36: =E35*E42 -> 13146.131 | F36: =F35*F42 -> 13907.857 | G36: =G35*G42 -> 14713.721 | H36: =H35*H42 -> 15566.279 | I36: =I35*I42 -> 16468.236
A37: CapEx | B37: =B38-B35+B36 -> 13117 | C37: =C38-C35+C36 -> 13410 | D37: =D38-D35+D36 -> 15852 | E37: =E35*E43 -> 16033.664 | F37: =F35*F43 -> 16962.703 | G37: =G35*G43 -> 17945.574 | H37: =H35*H43 -> 18985.395 | I37: =I35*I43 -> 20085.467
A38: Ending PP&E | B38: 43715 | C38: 45680 | D38: 49834 | E38: =E35-E36+E37 -> 52721.533 | F38: =F35-F36+F37 -> 55776.379 | G38: =G35-G36+G37 -> 59008.232 | H38: =H35-H36+H37 -> 62427.349 | I38: =I35-I36+I37 -> 66044.579
A40: Assumptions
A41: Fiscal Year | B41: 45122 | C41: 45489 | D41: 45856 | E41: 46223 | F41: 46590 | G41: 46957 | H41: 47324 | I41: 47691
A42: D&A as a % of Beginning PP&E | B42: =B36/B35 -> 0.27350001 | C42: =C36/C35 -> 0.26180945 | D42: =D36/D35 -> 0.25608581 | E42: =AVERAGE($B$42:$D$42) -> 0.26379842 | F42: =AVERAGE($B$42:$D$42) -> 0.26379842 | G42: =AVERAGE($B$42:$D$42) -> 0.26379842 | H42: =AVERAGE($B$42:$D$42) -> 0.26379842 | I42: =AVERAGE($B$42:$D$42) -> 0.26379842
A43: CapEx as a % of Beginning PP&E | B43: =B37/B35 -> 0.31144194 | C43: =C37/C35 -> 0.30675969 | D43: =D37/D35 -> 0.34702277 | E43: =AVERAGE($B$43:$D$43) -> 0.32174147 | F43: =AVERAGE($B$43:$D$43) -> 0.32174147 | G43: =AVERAGE($B$43:$D$43) -> 0.32174147 | H43: =AVERAGE($B$43:$D$43) -> 0.32174147 | I43: =AVERAGE($B$43:$D$43) -> 0.32174147
A47: Net Working Capital
A48: Fiscal Year | B48: 2022A | C48: 45122 | D48: 45489 | E48: 45856 | F48: 46223 | G48: 46590 | H48: 46957 | I48: 47324 | J48: 47691
...

Sheet WACC
A2: Weighted Average Cost of Capital (WACC)
A3: Equity (mm) | B3: =AVERAGE('Balance Sheet'!C35:D35) -> 65341.5
A4: Debt (mm) | B4: =AVERAGE('Balance Sheet'!C21+'Balance Sheet'!C24,'Balance Sheet'!D21+'Balance Sheet'!D24) -> 93670
A6: Cost of Debt | B6: =0.027670053385202 -> 0.027670053
A7: Tax Rate | B7: =AVERAGE('INCOME STATEMENT'!B13/'INCOME STATEMENT'!B14,'INCOME STATEMENT'!C13/'INCOME STATEMENT'!C14,'INCOME STATEMENT'!D13/'INCOME STATEMENT'!D14) -> 0.22498038
A8: D/(D+E) | B8: =B4/(B4+B3) -> 0.58907689
A9: After Tax Cost of Debt | B9: =(1-B7)*B6 -> 0.021444834
A11: Risk Free Rate (10-Yr Treasury Yield) | B11: 0.0422
A12: Expected Market Return | B12: 0.1322
A13: Market Risk Premium | B13: =B12-B11 -> 0.09
A14: Levered Beta | B14: 1.09
A15: E/(D+E) | B15: =B3/(B4+B3) -> 0.41092311
A16: Cost of Equity | B16: =B11+B14*B13 -> 0.1403
A18: WACC | B18: =B9*B8+B16*B15 -> 0.070285169

Sheet DCF
A1: Unlevered Free Cash Flow (mm)
A2: Fiscal Year | C2: 45122 | D2: 45489 | E2: 45856 | F2: 46223 | G2: 46590 | H2: 46957 | I2: 47324 | J2: 47691
A3: Unlevered Free Cash Flow | C3: =PROYECCIONES!B21 -> 103436 | D3: =PROYECCIONES!C21 -> 62457 | E3: =PROYECCIONES!D21 -> 114924 | F3: =PROYECCIONES!E21 -> 94821.874 | G3: =PROYECCIONES!F21 -> 98639.34 | H3: =PROYECCIONES!G21 -> 102942.85 | I3: =PROYECCIONES!H21 -> 107432.18 | J3: =PROYECCIONES!I21 -> 112115.24
A5: Projection Year | F5: 1 | G5: 2 | H5: 3 | I5: 4 | J5: 5
A6: Present Value of Free Cash Flow | F6: =F3/POWER(1+WACC!$B$18,F5) -> 88594.963 | G6: =G3/POWER(1+WACC!$B$18,G5) -> 86109.515 | H6: =H3/POWER(1+WACC!$B$18,H5) -> 83964.88 | I6: =I3/POWER(1+WACC!$B$18,I5) -> 81872.183 | J6: =J3/POWER(1+WACC!$B$18,J5) -> 79830.182
A8: Implied Share Price Calculation | D8: Sensitivity Table
A9: Sum of PV of FCF | B9: =SUM(F6:J6) -> 420371.72
A10: Growth Rate | B10: =PROYECCIONES!D25 -> 0.045 | F10: Growth Rate
A11: WACC | B11: =WACC!B18 -> 0.070285169 | E11: =B20 -> 244.05048 | F11: =G11-0.5% -> 0.035 | G11: =H11-0.5% -> 0.04 | H11: 0.045 | I11: =H11+0.5% -> 0.05 | J11: =I11+0.5% -> 0.055
A12: Terminal Value | B12: =J3*(1+B10)/(B11-B10) -> 4633563.2 | D12: WACC | E12: =E13-0.5% -> 0.060285169 | F12: 252.41169 | G12: 310.04482 | H12: 405.38321 | I12: 593.41663 | J12: 1137.2257
A13: PV of Terminal Value | B13: =B12/POWER(1+B11,J5) -> 3299267.7 | E13: =E14-0.5% -> 0.065285169 | F13: 210.29901 | G13: 248.18233 | H13: 304.74103 | I13: 398.30207 | J13: 582.83007
A14: Enterprise Value | B14: =B13+B9 -> 3719639.5 | E14: 0.070285169 | F14: 180.22687 | G14: 206.87012 | H14: 244.05048 | I14: 299.55967 | J14: 391.38459
A15: (+) Cash | B15: ='Balance Sheet'!D3 -> 35934 | E15: =E14+0.5% -> 0.075285169 | F15: 157.70905 | G15: 177.36869 | H15: 203.51983 | I15: 240.01345 | J15: 294.49737
A16: (-) Debt | B16: =-WACC!B4 -> -93670 | E16: =E15+0.5% -> 0.080285169 | F16: 140.24075 | G16: 155.27745 | H16: 174.57563 | I16: 200.24597 | J16: 236.06864
A17: (-) Minority Interest
A18: Equity Value | B18: =SUM(B14:B17)*1000000 -> 3.6619035e+12
A19: Diluted Shares Outstanding | B19: 15004697000
A20: Implied Share Price | B20: =B18/B19 -> 244.05048
A22: Considerando el siguiente rango | B22: Historic growth ( 5y) | C22: Good Scenary
A23: Revenue Growth | B23: 0.0327 | C23: 0.05
A24: Implied Share Price | B24: 161.73 | C24: 306.05
